[2022-10-06 11:17:57 +0900] [8283] [INFO] Starting gunicorn 20.1.0
[2022-10-06 11:17:57 +0900] [8283] [INFO] Listening at: http://0.0.0.0:8000 (8283)
[2022-10-06 11:17:57 +0900] [8283] [INFO] Using worker: sync
[2022-10-06 11:17:57 +0900] [8292] [INFO] Booting worker with pid: 8292
[2022-10-06 11:43:17 +0900] [25613] [INFO] Starting gunicorn 20.1.0
[2022-10-06 11:43:17 +0900] [25613] [ERROR] Connection in use: ('', 8000)
[2022-10-06 11:43:17 +0900] [25613] [ERROR] Retrying in 1 second.
[2022-10-06 11:43:18 +0900] [25613] [ERROR] Connection in use: ('', 8000)
[2022-10-06 11:43:18 +0900] [25613] [ERROR] Retrying in 1 second.
[2022-10-06 11:43:19 +0900] [25613] [ERROR] Connection in use: ('', 8000)
[2022-10-06 11:43:19 +0900] [25613] [ERROR] Retrying in 1 second.
[2022-10-06 11:43:20 +0900] [25613] [ERROR] Connection in use: ('', 8000)
[2022-10-06 11:43:20 +0900] [25613] [ERROR] Retrying in 1 second.
[2022-10-06 11:43:21 +0900] [25613] [ERROR] Connection in use: ('', 8000)
[2022-10-06 11:43:21 +0900] [25613] [ERROR] Retrying in 1 second.
[2022-10-06 11:43:22 +0900] [25613] [ERROR] Can't connect to ('', 8000)
[2022-10-06 02:44:40 +0000] [8292] [ERROR] Error handling request /
Traceback (most recent call last):
  File "/home/big/.local/lib/python3.8/site-packages/django/core/handlers/exception.py", line 55, in inner
    response = get_response(request)
  File "/home/big/.local/lib/python3.8/site-packages/django/utils/deprecation.py", line 135, in __call__
    response = self.process_request(request)
  File "/home/big/.local/lib/python3.8/site-packages/django/middleware/common.py", line 48, in process_request
    host = request.get_host()
  File "/home/big/.local/lib/python3.8/site-packages/django/http/request.py", line 148, in get_host
    raise DisallowedHost(msg)
django.core.exceptions.DisallowedHost: Invalid HTTP_HOST header: '127.0.0.1:8000'. You may need to add '127.0.0.1' to ALLOWED_HOSTS.

During handling of the above exception, another exception occurred:

Traceback (most recent call last):
  File "/home/big/.local/lib/python3.8/site-packages/django/core/handlers/exception.py", line 55, in inner
    response = get_response(request)
  File "/home/big/.local/lib/python3.8/site-packages/django/utils/deprecation.py", line 136, in __call__
    response = response or self.get_response(request)
  File "/home/big/.local/lib/python3.8/site-packages/django/core/handlers/exception.py", line 57, in inner
    response = response_for_exception(request, exc)
  File "/home/big/.local/lib/python3.8/site-packages/django/core/handlers/exception.py", line 124, in response_for_exception
    security_logger.error(
  File "/usr/lib/python3.8/logging/__init__.py", line 1475, in error
    self._log(ERROR, msg, args, **kwargs)
  File "/usr/lib/python3.8/logging/__init__.py", line 1589, in _log
    self.handle(record)
  File "/usr/lib/python3.8/logging/__init__.py", line 1599, in handle
    self.callHandlers(record)
  File "/usr/lib/python3.8/logging/__init__.py", line 1661, in callHandlers
    hdlr.handle(record)
  File "/usr/lib/python3.8/logging/__init__.py", line 954, in handle
    self.emit(record)
  File "/home/big/.local/lib/python3.8/site-packages/django/utils/log.py", line 125, in emit
    reporter.get_traceback_text(),
  File "/home/big/.local/lib/python3.8/site-packages/django/views/debug.py", line 403, in get_traceback_text
    c = Context(self.get_traceback_data(), autoescape=False, use_l10n=False)
  File "/home/big/.local/lib/python3.8/site-packages/django/views/debug.py", line 381, in get_traceback_data
    c["raising_view_name"] = get_caller(self.request)
  File "/home/big/.local/lib/python3.8/site-packages/django/views/debug.py", line 99, in get_caller
    resolver_match = resolve(request.path)
  File "/home/big/.local/lib/python3.8/site-packages/django/urls/base.py", line 24, in resolve
    return get_resolver(urlconf).resolve(path)
  File "/home/big/.local/lib/python3.8/site-packages/django/urls/resolvers.py", line 663, in resolve
    for pattern in self.url_patterns:
  File "/home/big/.local/lib/python3.8/site-packages/django/utils/functional.py", line 57, in __get__
    res = instance.__dict__[self.name] = self.func(instance)
  File "/home/big/.local/lib/python3.8/site-packages/django/urls/resolvers.py", line 715, in url_patterns
    patterns = getattr(self.urlconf_module, "urlpatterns", self.urlconf_module)
  File "/home/big/.local/lib/python3.8/site-packages/django/utils/functional.py", line 57, in __get__
    res = instance.__dict__[self.name] = self.func(instance)
  File "/home/big/.local/lib/python3.8/site-packages/django/urls/resolvers.py", line 708, in urlconf_module
    return import_module(self.urlconf_name)
  File "/usr/lib/python3.8/importlib/__init__.py", line 127, in import_module
    return _bootstrap._gcd_import(name[level:], package, level)
  File "<frozen importlib._bootstrap>", line 1014, in _gcd_import
  File "<frozen importlib._bootstrap>", line 991, in _find_and_load
  File "<frozen importlib._bootstrap>", line 975, in _find_and_load_unlocked
  File "<frozen importlib._bootstrap>", line 671, in _load_unlocked
  File "<frozen importlib._bootstrap_external>", line 848, in exec_module
  File "<frozen importlib._bootstrap>", line 219, in _call_with_frames_removed
  File "/home/big/study/movie_rest/app/urls.py", line 19, in <module>
    router = routers.DefaultRouter()
NameError: name 'routers' is not defined

During handling of the above exception, another exception occurred:

Traceback (most recent call last):
  File "/home/big/.local/lib/python3.8/site-packages/django/core/handlers/exception.py", line 55, in inner
    response = get_response(request)
  File "/home/big/.local/lib/python3.8/site-packages/django/utils/deprecation.py", line 136, in __call__
    response = response or self.get_response(request)
  File "/home/big/.local/lib/python3.8/site-packages/django/core/handlers/exception.py", line 57, in inner
    response = response_for_exception(request, exc)
  File "/home/big/.local/lib/python3.8/site-packages/django/core/handlers/exception.py", line 140, in response_for_exception
    response = handle_uncaught_exception(
  File "/home/big/.local/lib/python3.8/site-packages/django/core/handlers/exception.py", line 184, in handle_uncaught_exception
    callback = resolver.resolve_error_handler(500)
  File "/home/big/.local/lib/python3.8/site-packages/django/urls/resolvers.py", line 729, in resolve_error_handler
    callback = getattr(self.urlconf_module, "handler%s" % view_type, None)
  File "/home/big/.local/lib/python3.8/site-packages/django/utils/functional.py", line 57, in __get__
    res = instance.__dict__[self.name] = self.func(instance)
  File "/home/big/.local/lib/python3.8/site-packages/django/urls/resolvers.py", line 708, in urlconf_module
    return import_module(self.urlconf_name)
  File "/usr/lib/python3.8/importlib/__init__.py", line 127, in import_module
    return _bootstrap._gcd_import(name[level:], package, level)
  File "<frozen importlib._bootstrap>", line 1014, in _gcd_import
  File "<frozen importlib._bootstrap>", line 991, in _find_and_load
  File "<frozen importlib._bootstrap>", line 975, in _find_and_load_unlocked
  File "<frozen importlib._bootstrap>", line 671, in _load_unlocked
  File "<frozen importlib._bootstrap_external>", line 848, in exec_module
  File "<frozen importlib._bootstrap>", line 219, in _call_with_frames_removed
  File "/home/big/study/movie_rest/app/urls.py", line 19, in <module>
    router = routers.DefaultRouter()
NameError: name 'routers' is not defined

During handling of the above exception, another exception occurred:

Traceback (most recent call last):
  File "/home/big/.local/lib/python3.8/site-packages/gunicorn/workers/sync.py", line 136, in handle
    self.handle_request(listener, req, client, addr)
  File "/home/big/.local/lib/python3.8/site-packages/gunicorn/workers/sync.py", line 179, in handle_request
    respiter = self.wsgi(environ, resp.start_response)
  File "/home/big/.local/lib/python3.8/site-packages/django/core/handlers/wsgi.py", line 131, in __call__
    response = self.get_response(request)
  File "/home/big/.local/lib/python3.8/site-packages/django/core/handlers/base.py", line 140, in get_response
    response = self._middleware_chain(request)
  File "/home/big/.local/lib/python3.8/site-packages/django/core/handlers/exception.py", line 57, in inner
    response = response_for_exception(request, exc)
  File "/home/big/.local/lib/python3.8/site-packages/django/core/handlers/exception.py", line 140, in response_for_exception
    response = handle_uncaught_exception(
  File "/home/big/.local/lib/python3.8/site-packages/django/core/handlers/exception.py", line 184, in handle_uncaught_exception
    callback = resolver.resolve_error_handler(500)
  File "/home/big/.local/lib/python3.8/site-packages/django/urls/resolvers.py", line 729, in resolve_error_handler
    callback = getattr(self.urlconf_module, "handler%s" % view_type, None)
  File "/home/big/.local/lib/python3.8/site-packages/django/utils/functional.py", line 57, in __get__
    res = instance.__dict__[self.name] = self.func(instance)
  File "/home/big/.local/lib/python3.8/site-packages/django/urls/resolvers.py", line 708, in urlconf_module
    return import_module(self.urlconf_name)
  File "/usr/lib/python3.8/importlib/__init__.py", line 127, in import_module
    return _bootstrap._gcd_import(name[level:], package, level)
  File "<frozen importlib._bootstrap>", line 1014, in _gcd_import
  File "<frozen importlib._bootstrap>", line 991, in _find_and_load
  File "<frozen importlib._bootstrap>", line 975, in _find_and_load_unlocked
  File "<frozen importlib._bootstrap>", line 671, in _load_unlocked
  File "<frozen importlib._bootstrap_external>", line 848, in exec_module
  File "<frozen importlib._bootstrap>", line 219, in _call_with_frames_removed
  File "/home/big/study/movie_rest/app/urls.py", line 19, in <module>
    router = routers.DefaultRouter()
NameError: name 'routers' is not defined
[2022-10-06 02:44:40 +0000] [8292] [ERROR] Error handling request /favicon.ico
Traceback (most recent call last):
  File "/home/big/.local/lib/python3.8/site-packages/django/core/handlers/exception.py", line 55, in inner
    response = get_response(request)
  File "/home/big/.local/lib/python3.8/site-packages/django/utils/deprecation.py", line 135, in __call__
    response = self.process_request(request)
  File "/home/big/.local/lib/python3.8/site-packages/django/middleware/common.py", line 48, in process_request
    host = request.get_host()
  File "/home/big/.local/lib/python3.8/site-packages/django/http/request.py", line 148, in get_host
    raise DisallowedHost(msg)
django.core.exceptions.DisallowedHost: Invalid HTTP_HOST header: '127.0.0.1:8000'. You may need to add '127.0.0.1' to ALLOWED_HOSTS.

During handling of the above exception, another exception occurred:

Traceback (most recent call last):
  File "/home/big/.local/lib/python3.8/site-packages/django/core/handlers/exception.py", line 55, in inner
    response = get_response(request)
  File "/home/big/.local/lib/python3.8/site-packages/django/utils/deprecation.py", line 136, in __call__
    response = response or self.get_response(request)
  File "/home/big/.local/lib/python3.8/site-packages/django/core/handlers/exception.py", line 57, in inner
    response = response_for_exception(request, exc)
  File "/home/big/.local/lib/python3.8/site-packages/django/core/handlers/exception.py", line 124, in response_for_exception
    security_logger.error(
  File "/usr/lib/python3.8/logging/__init__.py", line 1475, in error
    self._log(ERROR, msg, args, **kwargs)
  File "/usr/lib/python3.8/logging/__init__.py", line 1589, in _log
    self.handle(record)
  File "/usr/lib/python3.8/logging/__init__.py", line 1599, in handle
    self.callHandlers(record)
  File "/usr/lib/python3.8/logging/__init__.py", line 1661, in callHandlers
    hdlr.handle(record)
  File "/usr/lib/python3.8/logging/__init__.py", line 954, in handle
    self.emit(record)
  File "/home/big/.local/lib/python3.8/site-packages/django/utils/log.py", line 125, in emit
    reporter.get_traceback_text(),
  File "/home/big/.local/lib/python3.8/site-packages/django/views/debug.py", line 403, in get_traceback_text
    c = Context(self.get_traceback_data(), autoescape=False, use_l10n=False)
  File "/home/big/.local/lib/python3.8/site-packages/django/views/debug.py", line 381, in get_traceback_data
    c["raising_view_name"] = get_caller(self.request)
  File "/home/big/.local/lib/python3.8/site-packages/django/views/debug.py", line 99, in get_caller
    resolver_match = resolve(request.path)
  File "/home/big/.local/lib/python3.8/site-packages/django/urls/base.py", line 24, in resolve
    return get_resolver(urlconf).resolve(path)
  File "/home/big/.local/lib/python3.8/site-packages/django/urls/resolvers.py", line 663, in resolve
    for pattern in self.url_patterns:
  File "/home/big/.local/lib/python3.8/site-packages/django/utils/functional.py", line 57, in __get__
    res = instance.__dict__[self.name] = self.func(instance)
  File "/home/big/.local/lib/python3.8/site-packages/django/urls/resolvers.py", line 715, in url_patterns
    patterns = getattr(self.urlconf_module, "urlpatterns", self.urlconf_module)
  File "/home/big/.local/lib/python3.8/site-packages/django/utils/functional.py", line 57, in __get__
    res = instance.__dict__[self.name] = self.func(instance)
  File "/home/big/.local/lib/python3.8/site-packages/django/urls/resolvers.py", line 708, in urlconf_module
    return import_module(self.urlconf_name)
  File "/usr/lib/python3.8/importlib/__init__.py", line 127, in import_module
    return _bootstrap._gcd_import(name[level:], package, level)
  File "<frozen importlib._bootstrap>", line 1014, in _gcd_import
  File "<frozen importlib._bootstrap>", line 991, in _find_and_load
  File "<frozen importlib._bootstrap>", line 975, in _find_and_load_unlocked
  File "<frozen importlib._bootstrap>", line 671, in _load_unlocked
  File "<frozen importlib._bootstrap_external>", line 848, in exec_module
  File "<frozen importlib._bootstrap>", line 219, in _call_with_frames_removed
  File "/home/big/study/movie_rest/app/urls.py", line 19, in <module>
    router = routers.DefaultRouter()
NameError: name 'routers' is not defined

During handling of the above exception, another exception occurred:

Traceback (most recent call last):
  File "/home/big/.local/lib/python3.8/site-packages/django/core/handlers/exception.py", line 55, in inner
    response = get_response(request)
  File "/home/big/.local/lib/python3.8/site-packages/django/utils/deprecation.py", line 136, in __call__
    response = response or self.get_response(request)
  File "/home/big/.local/lib/python3.8/site-packages/django/core/handlers/exception.py", line 57, in inner
    response = response_for_exception(request, exc)
  File "/home/big/.local/lib/python3.8/site-packages/django/core/handlers/exception.py", line 140, in response_for_exception
    response = handle_uncaught_exception(
  File "/home/big/.local/lib/python3.8/site-packages/django/core/handlers/exception.py", line 184, in handle_uncaught_exception
    callback = resolver.resolve_error_handler(500)
  File "/home/big/.local/lib/python3.8/site-packages/django/urls/resolvers.py", line 729, in resolve_error_handler
    callback = getattr(self.urlconf_module, "handler%s" % view_type, None)
  File "/home/big/.local/lib/python3.8/site-packages/django/utils/functional.py", line 57, in __get__
    res = instance.__dict__[self.name] = self.func(instance)
  File "/home/big/.local/lib/python3.8/site-packages/django/urls/resolvers.py", line 708, in urlconf_module
    return import_module(self.urlconf_name)
  File "/usr/lib/python3.8/importlib/__init__.py", line 127, in import_module
    return _bootstrap._gcd_import(name[level:], package, level)
  File "<frozen importlib._bootstrap>", line 1014, in _gcd_import
  File "<frozen importlib._bootstrap>", line 991, in _find_and_load
  File "<frozen importlib._bootstrap>", line 975, in _find_and_load_unlocked
  File "<frozen importlib._bootstrap>", line 671, in _load_unlocked
  File "<frozen importlib._bootstrap_external>", line 848, in exec_module
  File "<frozen importlib._bootstrap>", line 219, in _call_with_frames_removed
  File "/home/big/study/movie_rest/app/urls.py", line 19, in <module>
    router = routers.DefaultRouter()
NameError: name 'routers' is not defined

During handling of the above exception, another exception occurred:

Traceback (most recent call last):
  File "/home/big/.local/lib/python3.8/site-packages/gunicorn/workers/sync.py", line 136, in handle
    self.handle_request(listener, req, client, addr)
  File "/home/big/.local/lib/python3.8/site-packages/gunicorn/workers/sync.py", line 179, in handle_request
    respiter = self.wsgi(environ, resp.start_response)
  File "/home/big/.local/lib/python3.8/site-packages/django/core/handlers/wsgi.py", line 131, in __call__
    response = self.get_response(request)
  File "/home/big/.local/lib/python3.8/site-packages/django/core/handlers/base.py", line 140, in get_response
    response = self._middleware_chain(request)
  File "/home/big/.local/lib/python3.8/site-packages/django/core/handlers/exception.py", line 57, in inner
    response = response_for_exception(request, exc)
  File "/home/big/.local/lib/python3.8/site-packages/django/core/handlers/exception.py", line 140, in response_for_exception
    response = handle_uncaught_exception(
  File "/home/big/.local/lib/python3.8/site-packages/django/core/handlers/exception.py", line 184, in handle_uncaught_exception
    callback = resolver.resolve_error_handler(500)
  File "/home/big/.local/lib/python3.8/site-packages/django/urls/resolvers.py", line 729, in resolve_error_handler
    callback = getattr(self.urlconf_module, "handler%s" % view_type, None)
  File "/home/big/.local/lib/python3.8/site-packages/django/utils/functional.py", line 57, in __get__
    res = instance.__dict__[self.name] = self.func(instance)
  File "/home/big/.local/lib/python3.8/site-packages/django/urls/resolvers.py", line 708, in urlconf_module
    return import_module(self.urlconf_name)
  File "/usr/lib/python3.8/importlib/__init__.py", line 127, in import_module
    return _bootstrap._gcd_import(name[level:], package, level)
  File "<frozen importlib._bootstrap>", line 1014, in _gcd_import
  File "<frozen importlib._bootstrap>", line 991, in _find_and_load
  File "<frozen importlib._bootstrap>", line 975, in _find_and_load_unlocked
  File "<frozen importlib._bootstrap>", line 671, in _load_unlocked
  File "<frozen importlib._bootstrap_external>", line 848, in exec_module
  File "<frozen importlib._bootstrap>", line 219, in _call_with_frames_removed
  File "/home/big/study/movie_rest/app/urls.py", line 19, in <module>
    router = routers.DefaultRouter()
NameError: name 'routers' is not defined
[2022-10-06 11:45:16 +0900] [8283] [CRITICAL] WORKER TIMEOUT (pid:8292)
[2022-10-06 02:45:16 +0000] [8292] [INFO] Worker exiting (pid: 8292)
[2022-10-06 11:45:16 +0900] [27113] [INFO] Booting worker with pid: 27113
[2022-10-06 02:45:16 +0000] [27113] [ERROR] Error handling request /
Traceback (most recent call last):
  File "/home/big/.local/lib/python3.8/site-packages/django/core/handlers/exception.py", line 55, in inner
    response = get_response(request)
  File "/home/big/.local/lib/python3.8/site-packages/django/utils/deprecation.py", line 135, in __call__
    response = self.process_request(request)
  File "/home/big/.local/lib/python3.8/site-packages/django/middleware/common.py", line 48, in process_request
    host = request.get_host()
  File "/home/big/.local/lib/python3.8/site-packages/django/http/request.py", line 148, in get_host
    raise DisallowedHost(msg)
django.core.exceptions.DisallowedHost: Invalid HTTP_HOST header: '127.0.0.1:8000'. You may need to add '127.0.0.1' to ALLOWED_HOSTS.

During handling of the above exception, another exception occurred:

Traceback (most recent call last):
  File "/home/big/.local/lib/python3.8/site-packages/django/core/handlers/exception.py", line 55, in inner
    response = get_response(request)
  File "/home/big/.local/lib/python3.8/site-packages/django/utils/deprecation.py", line 136, in __call__
    response = response or self.get_response(request)
  File "/home/big/.local/lib/python3.8/site-packages/django/core/handlers/exception.py", line 57, in inner
    response = response_for_exception(request, exc)
  File "/home/big/.local/lib/python3.8/site-packages/django/core/handlers/exception.py", line 124, in response_for_exception
    security_logger.error(
  File "/usr/lib/python3.8/logging/__init__.py", line 1475, in error
    self._log(ERROR, msg, args, **kwargs)
  File "/usr/lib/python3.8/logging/__init__.py", line 1589, in _log
    self.handle(record)
  File "/usr/lib/python3.8/logging/__init__.py", line 1599, in handle
    self.callHandlers(record)
  File "/usr/lib/python3.8/logging/__init__.py", line 1661, in callHandlers
    hdlr.handle(record)
  File "/usr/lib/python3.8/logging/__init__.py", line 954, in handle
    self.emit(record)
  File "/home/big/.local/lib/python3.8/site-packages/django/utils/log.py", line 125, in emit
    reporter.get_traceback_text(),
  File "/home/big/.local/lib/python3.8/site-packages/django/views/debug.py", line 403, in get_traceback_text
    c = Context(self.get_traceback_data(), autoescape=False, use_l10n=False)
  File "/home/big/.local/lib/python3.8/site-packages/django/views/debug.py", line 381, in get_traceback_data
    c["raising_view_name"] = get_caller(self.request)
  File "/home/big/.local/lib/python3.8/site-packages/django/views/debug.py", line 99, in get_caller
    resolver_match = resolve(request.path)
  File "/home/big/.local/lib/python3.8/site-packages/django/urls/base.py", line 24, in resolve
    return get_resolver(urlconf).resolve(path)
  File "/home/big/.local/lib/python3.8/site-packages/django/urls/resolvers.py", line 663, in resolve
    for pattern in self.url_patterns:
  File "/home/big/.local/lib/python3.8/site-packages/django/utils/functional.py", line 57, in __get__
    res = instance.__dict__[self.name] = self.func(instance)
  File "/home/big/.local/lib/python3.8/site-packages/django/urls/resolvers.py", line 715, in url_patterns
    patterns = getattr(self.urlconf_module, "urlpatterns", self.urlconf_module)
  File "/home/big/.local/lib/python3.8/site-packages/django/utils/functional.py", line 57, in __get__
    res = instance.__dict__[self.name] = self.func(instance)
  File "/home/big/.local/lib/python3.8/site-packages/django/urls/resolvers.py", line 708, in urlconf_module
    return import_module(self.urlconf_name)
  File "/usr/lib/python3.8/importlib/__init__.py", line 127, in import_module
    return _bootstrap._gcd_import(name[level:], package, level)
  File "<frozen importlib._bootstrap>", line 1014, in _gcd_import
  File "<frozen importlib._bootstrap>", line 991, in _find_and_load
  File "<frozen importlib._bootstrap>", line 975, in _find_and_load_unlocked
  File "<frozen importlib._bootstrap>", line 671, in _load_unlocked
  File "<frozen importlib._bootstrap_external>", line 848, in exec_module
  File "<frozen importlib._bootstrap>", line 219, in _call_with_frames_removed
  File "/home/big/study/movie_rest/app/urls.py", line 19, in <module>
    router = routers.DefaultRouter()
NameError: name 'routers' is not defined

During handling of the above exception, another exception occurred:

Traceback (most recent call last):
  File "/home/big/.local/lib/python3.8/site-packages/django/core/handlers/exception.py", line 55, in inner
    response = get_response(request)
  File "/home/big/.local/lib/python3.8/site-packages/django/utils/deprecation.py", line 136, in __call__
    response = response or self.get_response(request)
  File "/home/big/.local/lib/python3.8/site-packages/django/core/handlers/exception.py", line 57, in inner
    response = response_for_exception(request, exc)
  File "/home/big/.local/lib/python3.8/site-packages/django/core/handlers/exception.py", line 140, in response_for_exception
    response = handle_uncaught_exception(
  File "/home/big/.local/lib/python3.8/site-packages/django/core/handlers/exception.py", line 184, in handle_uncaught_exception
    callback = resolver.resolve_error_handler(500)
  File "/home/big/.local/lib/python3.8/site-packages/django/urls/resolvers.py", line 729, in resolve_error_handler
    callback = getattr(self.urlconf_module, "handler%s" % view_type, None)
  File "/home/big/.local/lib/python3.8/site-packages/django/utils/functional.py", line 57, in __get__
    res = instance.__dict__[self.name] = self.func(instance)
  File "/home/big/.local/lib/python3.8/site-packages/django/urls/resolvers.py", line 708, in urlconf_module
    return import_module(self.urlconf_name)
  File "/usr/lib/python3.8/importlib/__init__.py", line 127, in import_module
    return _bootstrap._gcd_import(name[level:], package, level)
  File "<frozen importlib._bootstrap>", line 1014, in _gcd_import
  File "<frozen importlib._bootstrap>", line 991, in _find_and_load
  File "<frozen importlib._bootstrap>", line 975, in _find_and_load_unlocked
  File "<frozen importlib._bootstrap>", line 671, in _load_unlocked
  File "<frozen importlib._bootstrap_external>", line 848, in exec_module
  File "<frozen importlib._bootstrap>", line 219, in _call_with_frames_removed
  File "/home/big/study/movie_rest/app/urls.py", line 19, in <module>
    router = routers.DefaultRouter()
NameError: name 'routers' is not defined

During handling of the above exception, another exception occurred:

Traceback (most recent call last):
  File "/home/big/.local/lib/python3.8/site-packages/gunicorn/workers/sync.py", line 136, in handle
    self.handle_request(listener, req, client, addr)
  File "/home/big/.local/lib/python3.8/site-packages/gunicorn/workers/sync.py", line 179, in handle_request
    respiter = self.wsgi(environ, resp.start_response)
  File "/home/big/.local/lib/python3.8/site-packages/django/core/handlers/wsgi.py", line 131, in __call__
    response = self.get_response(request)
  File "/home/big/.local/lib/python3.8/site-packages/django/core/handlers/base.py", line 140, in get_response
    response = self._middleware_chain(request)
  File "/home/big/.local/lib/python3.8/site-packages/django/core/handlers/exception.py", line 57, in inner
    response = response_for_exception(request, exc)
  File "/home/big/.local/lib/python3.8/site-packages/django/core/handlers/exception.py", line 140, in response_for_exception
    response = handle_uncaught_exception(
  File "/home/big/.local/lib/python3.8/site-packages/django/core/handlers/exception.py", line 184, in handle_uncaught_exception
    callback = resolver.resolve_error_handler(500)
  File "/home/big/.local/lib/python3.8/site-packages/django/urls/resolvers.py", line 729, in resolve_error_handler
    callback = getattr(self.urlconf_module, "handler%s" % view_type, None)
  File "/home/big/.local/lib/python3.8/site-packages/django/utils/functional.py", line 57, in __get__
    res = instance.__dict__[self.name] = self.func(instance)
  File "/home/big/.local/lib/python3.8/site-packages/django/urls/resolvers.py", line 708, in urlconf_module
    return import_module(self.urlconf_name)
  File "/usr/lib/python3.8/importlib/__init__.py", line 127, in import_module
    return _bootstrap._gcd_import(name[level:], package, level)
  File "<frozen importlib._bootstrap>", line 1014, in _gcd_import
  File "<frozen importlib._bootstrap>", line 991, in _find_and_load
  File "<frozen importlib._bootstrap>", line 975, in _find_and_load_unlocked
  File "<frozen importlib._bootstrap>", line 671, in _load_unlocked
  File "<frozen importlib._bootstrap_external>", line 848, in exec_module
  File "<frozen importlib._bootstrap>", line 219, in _call_with_frames_removed
  File "/home/big/study/movie_rest/app/urls.py", line 19, in <module>
    router = routers.DefaultRouter()
NameError: name 'routers' is not defined
[2022-10-06 02:46:16 +0000] [27113] [INFO] Parent changed, shutting down: <Worker 27113>
[2022-10-06 02:46:16 +0000] [27113] [INFO] Worker exiting (pid: 27113)
[2022-10-06 11:46:39 +0900] [28223] [INFO] Starting gunicorn 20.1.0
[2022-10-06 11:46:39 +0900] [28223] [INFO] Listening at: http://0.0.0.0:8000 (28223)
[2022-10-06 11:46:39 +0900] [28223] [INFO] Using worker: sync
[2022-10-06 11:46:39 +0900] [28225] [INFO] Booting worker with pid: 28225
[2022-10-06 11:47:24 +0900] [28223] [INFO] Handling signal: winch
[2022-10-06 11:47:24 +0900] [28223] [INFO] Handling signal: winch
[2022-10-06 11:47:24 +0900] [28223] [INFO] Handling signal: winch
[2022-10-06 11:48:16 +0900] [28223] [INFO] Handling signal: winch
[2022-10-06 11:48:17 +0900] [28223] [INFO] Handling signal: winch
[2022-10-06 11:48:23 +0900] [28223] [INFO] Handling signal: int
[2022-10-06 02:48:23 +0000] [28225] [INFO] Worker exiting (pid: 28225)
[2022-10-06 11:48:23 +0900] [28223] [INFO] Shutting down: Master
[2022-10-06 15:12:41 +0900] [809] [INFO] Starting gunicorn 20.1.0
[2022-10-06 15:12:41 +0900] [809] [INFO] Listening at: http://0.0.0.0:8000 (809)
[2022-10-06 15:12:41 +0900] [809] [INFO] Using worker: sync
[2022-10-06 15:12:41 +0900] [815] [INFO] Booting worker with pid: 815
[2022-10-06 06:12:41 +0000] [815] [ERROR] Exception in worker process
Traceback (most recent call last):
  File "/home/big/.local/lib/python3.8/site-packages/gunicorn/arbiter.py", line 589, in spawn_worker
    worker.init_process()
  File "/home/big/.local/lib/python3.8/site-packages/gunicorn/workers/base.py", line 134, in init_process
    self.load_wsgi()
  File "/home/big/.local/lib/python3.8/site-packages/gunicorn/workers/base.py", line 146, in load_wsgi
    self.wsgi = self.app.wsgi()
  File "/home/big/.local/lib/python3.8/site-packages/gunicorn/app/base.py", line 67, in wsgi
    self.callable = self.load()
  File "/home/big/.local/lib/python3.8/site-packages/gunicorn/app/wsgiapp.py", line 58, in load
    return self.load_wsgiapp()
  File "/home/big/.local/lib/python3.8/site-packages/gunicorn/app/wsgiapp.py", line 48, in load_wsgiapp
    return util.import_app(self.app_uri)
  File "/home/big/.local/lib/python3.8/site-packages/gunicorn/util.py", line 359, in import_app
    mod = importlib.import_module(module)
  File "/usr/lib/python3.8/importlib/__init__.py", line 127, in import_module
    return _bootstrap._gcd_import(name[level:], package, level)
  File "<frozen importlib._bootstrap>", line 1014, in _gcd_import
  File "<frozen importlib._bootstrap>", line 991, in _find_and_load
  File "<frozen importlib._bootstrap>", line 975, in _find_and_load_unlocked
  File "<frozen importlib._bootstrap>", line 671, in _load_unlocked
  File "<frozen importlib._bootstrap_external>", line 848, in exec_module
  File "<frozen importlib._bootstrap>", line 219, in _call_with_frames_removed
  File "/home/big/study/movie_rest/app/wsgi.py", line 16, in <module>
    application = get_wsgi_application()
  File "/home/big/.local/lib/python3.8/site-packages/django/core/wsgi.py", line 12, in get_wsgi_application
    django.setup(set_prefix=False)
  File "/home/big/.local/lib/python3.8/site-packages/django/__init__.py", line 24, in setup
    apps.populate(settings.INSTALLED_APPS)
  File "/home/big/.local/lib/python3.8/site-packages/django/apps/registry.py", line 91, in populate
    app_config = AppConfig.create(entry)
  File "/home/big/.local/lib/python3.8/site-packages/django/apps/config.py", line 193, in create
    import_module(entry)
  File "/usr/lib/python3.8/importlib/__init__.py", line 127, in import_module
    return _bootstrap._gcd_import(name[level:], package, level)
  File "<frozen importlib._bootstrap>", line 1014, in _gcd_import
  File "<frozen importlib._bootstrap>", line 991, in _find_and_load
  File "<frozen importlib._bootstrap>", line 973, in _find_and_load_unlocked
ModuleNotFoundError: No module named 'corsheaders'
[2022-10-06 06:12:41 +0000] [815] [INFO] Worker exiting (pid: 815)
[2022-10-06 15:12:41 +0900] [809] [INFO] Shutting down: Master
[2022-10-06 15:12:41 +0900] [809] [INFO] Reason: Worker failed to boot.
[2022-10-06 15:12:48 +0900] [894] [INFO] Starting gunicorn 20.1.0
[2022-10-06 15:12:48 +0900] [894] [INFO] Listening at: http://0.0.0.0:8000 (894)
[2022-10-06 15:12:48 +0900] [894] [INFO] Using worker: sync
[2022-10-06 15:12:48 +0900] [899] [INFO] Booting worker with pid: 899
[2022-10-06 06:12:48 +0000] [899] [ERROR] Exception in worker process
Traceback (most recent call last):
  File "/home/big/.local/lib/python3.8/site-packages/gunicorn/arbiter.py", line 589, in spawn_worker
    worker.init_process()
  File "/home/big/.local/lib/python3.8/site-packages/gunicorn/workers/base.py", line 134, in init_process
    self.load_wsgi()
  File "/home/big/.local/lib/python3.8/site-packages/gunicorn/workers/base.py", line 146, in load_wsgi
    self.wsgi = self.app.wsgi()
  File "/home/big/.local/lib/python3.8/site-packages/gunicorn/app/base.py", line 67, in wsgi
    self.callable = self.load()
  File "/home/big/.local/lib/python3.8/site-packages/gunicorn/app/wsgiapp.py", line 58, in load
    return self.load_wsgiapp()
  File "/home/big/.local/lib/python3.8/site-packages/gunicorn/app/wsgiapp.py", line 48, in load_wsgiapp
    return util.import_app(self.app_uri)
  File "/home/big/.local/lib/python3.8/site-packages/gunicorn/util.py", line 359, in import_app
    mod = importlib.import_module(module)
  File "/usr/lib/python3.8/importlib/__init__.py", line 127, in import_module
    return _bootstrap._gcd_import(name[level:], package, level)
  File "<frozen importlib._bootstrap>", line 1014, in _gcd_import
  File "<frozen importlib._bootstrap>", line 991, in _find_and_load
  File "<frozen importlib._bootstrap>", line 975, in _find_and_load_unlocked
  File "<frozen importlib._bootstrap>", line 671, in _load_unlocked
  File "<frozen importlib._bootstrap_external>", line 848, in exec_module
  File "<frozen importlib._bootstrap>", line 219, in _call_with_frames_removed
  File "/home/big/study/movie_rest/app/wsgi.py", line 16, in <module>
    application = get_wsgi_application()
  File "/home/big/.local/lib/python3.8/site-packages/django/core/wsgi.py", line 12, in get_wsgi_application
    django.setup(set_prefix=False)
  File "/home/big/.local/lib/python3.8/site-packages/django/__init__.py", line 24, in setup
    apps.populate(settings.INSTALLED_APPS)
  File "/home/big/.local/lib/python3.8/site-packages/django/apps/registry.py", line 91, in populate
    app_config = AppConfig.create(entry)
  File "/home/big/.local/lib/python3.8/site-packages/django/apps/config.py", line 193, in create
    import_module(entry)
  File "/usr/lib/python3.8/importlib/__init__.py", line 127, in import_module
    return _bootstrap._gcd_import(name[level:], package, level)
  File "<frozen importlib._bootstrap>", line 1014, in _gcd_import
  File "<frozen importlib._bootstrap>", line 991, in _find_and_load
  File "<frozen importlib._bootstrap>", line 973, in _find_and_load_unlocked
ModuleNotFoundError: No module named 'corsheaders'
[2022-10-06 06:12:48 +0000] [899] [INFO] Worker exiting (pid: 899)
[2022-10-06 15:12:48 +0900] [894] [INFO] Shutting down: Master
[2022-10-06 15:12:48 +0900] [894] [INFO] Reason: Worker failed to boot.
[2022-10-06 15:59:23 +0900] [1211] [INFO] Starting gunicorn 20.1.0
[2022-10-06 15:59:23 +0900] [1211] [INFO] Listening at: http://0.0.0.0:8000 (1211)
[2022-10-06 15:59:23 +0900] [1211] [INFO] Using worker: sync
[2022-10-06 15:59:23 +0900] [1221] [INFO] Booting worker with pid: 1221
[2022-10-06 07:06:30 +0000] [1221] [ERROR] Error handling request /doc/
Traceback (most recent call last):
  File "/home/big/.local/lib/python3.8/site-packages/django/core/handlers/exception.py", line 55, in inner
    response = get_response(request)
  File "/home/big/.local/lib/python3.8/site-packages/django/core/handlers/base.py", line 181, in _get_response
    callback, callback_args, callback_kwargs = self.resolve_request(request)
  File "/home/big/.local/lib/python3.8/site-packages/django/core/handlers/base.py", line 313, in resolve_request
    resolver_match = resolver.resolve(request.path_info)
  File "/home/big/.local/lib/python3.8/site-packages/django/urls/resolvers.py", line 663, in resolve
    for pattern in self.url_patterns:
  File "/home/big/.local/lib/python3.8/site-packages/django/utils/functional.py", line 57, in __get__
    res = instance.__dict__[self.name] = self.func(instance)
  File "/home/big/.local/lib/python3.8/site-packages/django/urls/resolvers.py", line 715, in url_patterns
    patterns = getattr(self.urlconf_module, "urlpatterns", self.urlconf_module)
  File "/home/big/.local/lib/python3.8/site-packages/django/utils/functional.py", line 57, in __get__
    res = instance.__dict__[self.name] = self.func(instance)
  File "/home/big/.local/lib/python3.8/site-packages/django/urls/resolvers.py", line 708, in urlconf_module
    return import_module(self.urlconf_name)
  File "/usr/lib/python3.8/importlib/__init__.py", line 127, in import_module
    return _bootstrap._gcd_import(name[level:], package, level)
  File "<frozen importlib._bootstrap>", line 1014, in _gcd_import
  File "<frozen importlib._bootstrap>", line 991, in _find_and_load
  File "<frozen importlib._bootstrap>", line 975, in _find_and_load_unlocked
  File "<frozen importlib._bootstrap>", line 671, in _load_unlocked
  File "<frozen importlib._bootstrap_external>", line 848, in exec_module
  File "<frozen importlib._bootstrap>", line 219, in _call_with_frames_removed
  File "/home/big/study/movie_rest/app/urls.py", line 22, in <module>
    from rest_api import views as rest_view
  File "/home/big/study/movie_rest/rest_api/views.py", line 40
    <<<<<<< HEAD
    ^
SyntaxError: invalid syntax

During handling of the above exception, another exception occurred:

Traceback (most recent call last):
  File "/home/big/.local/lib/python3.8/site-packages/django/core/handlers/exception.py", line 55, in inner
    response = get_response(request)
  File "/home/big/.local/lib/python3.8/site-packages/django/utils/deprecation.py", line 136, in __call__
    response = response or self.get_response(request)
  File "/home/big/.local/lib/python3.8/site-packages/django/core/handlers/exception.py", line 57, in inner
    response = response_for_exception(request, exc)
  File "/home/big/.local/lib/python3.8/site-packages/django/core/handlers/exception.py", line 140, in response_for_exception
    response = handle_uncaught_exception(
  File "/home/big/.local/lib/python3.8/site-packages/django/core/handlers/exception.py", line 181, in handle_uncaught_exception
    return debug.technical_500_response(request, *exc_info)
  File "/home/big/.local/lib/python3.8/site-packages/django/views/debug.py", line 66, in technical_500_response
    html = reporter.get_traceback_html()
  File "/home/big/.local/lib/python3.8/site-packages/django/views/debug.py", line 396, in get_traceback_html
    c = Context(self.get_traceback_data(), use_l10n=False)
  File "/home/big/.local/lib/python3.8/site-packages/django/views/debug.py", line 381, in get_traceback_data
    c["raising_view_name"] = get_caller(self.request)
  File "/home/big/.local/lib/python3.8/site-packages/django/views/debug.py", line 99, in get_caller
    resolver_match = resolve(request.path)
  File "/home/big/.local/lib/python3.8/site-packages/django/urls/base.py", line 24, in resolve
    return get_resolver(urlconf).resolve(path)
  File "/home/big/.local/lib/python3.8/site-packages/django/urls/resolvers.py", line 663, in resolve
    for pattern in self.url_patterns:
  File "/home/big/.local/lib/python3.8/site-packages/django/utils/functional.py", line 57, in __get__
    res = instance.__dict__[self.name] = self.func(instance)
  File "/home/big/.local/lib/python3.8/site-packages/django/urls/resolvers.py", line 715, in url_patterns
    patterns = getattr(self.urlconf_module, "urlpatterns", self.urlconf_module)
  File "/home/big/.local/lib/python3.8/site-packages/django/utils/functional.py", line 57, in __get__
    res = instance.__dict__[self.name] = self.func(instance)
  File "/home/big/.local/lib/python3.8/site-packages/django/urls/resolvers.py", line 708, in urlconf_module
    return import_module(self.urlconf_name)
  File "/usr/lib/python3.8/importlib/__init__.py", line 127, in import_module
    return _bootstrap._gcd_import(name[level:], package, level)
  File "<frozen importlib._bootstrap>", line 1014, in _gcd_import
  File "<frozen importlib._bootstrap>", line 991, in _find_and_load
  File "<frozen importlib._bootstrap>", line 975, in _find_and_load_unlocked
  File "<frozen importlib._bootstrap>", line 671, in _load_unlocked
  File "<frozen importlib._bootstrap_external>", line 848, in exec_module
  File "<frozen importlib._bootstrap>", line 219, in _call_with_frames_removed
  File "/home/big/study/movie_rest/app/urls.py", line 22, in <module>
    from rest_api import views as rest_view
  File "/home/big/study/movie_rest/rest_api/views.py", line 40
    <<<<<<< HEAD
    ^
SyntaxError: invalid syntax

During handling of the above exception, another exception occurred:

Traceback (most recent call last):
  File "/home/big/.local/lib/python3.8/site-packages/django/core/handlers/exception.py", line 55, in inner
    response = get_response(request)
  File "/home/big/.local/lib/python3.8/site-packages/django/utils/deprecation.py", line 136, in __call__
    response = response or self.get_response(request)
  File "/home/big/.local/lib/python3.8/site-packages/django/core/handlers/exception.py", line 57, in inner
    response = response_for_exception(request, exc)
  File "/home/big/.local/lib/python3.8/site-packages/django/core/handlers/exception.py", line 140, in response_for_exception
    response = handle_uncaught_exception(
  File "/home/big/.local/lib/python3.8/site-packages/django/core/handlers/exception.py", line 181, in handle_uncaught_exception
    return debug.technical_500_response(request, *exc_info)
  File "/home/big/.local/lib/python3.8/site-packages/django/views/debug.py", line 66, in technical_500_response
    html = reporter.get_traceback_html()
  File "/home/big/.local/lib/python3.8/site-packages/django/views/debug.py", line 396, in get_traceback_html
    c = Context(self.get_traceback_data(), use_l10n=False)
  File "/home/big/.local/lib/python3.8/site-packages/django/views/debug.py", line 381, in get_traceback_data
    c["raising_view_name"] = get_caller(self.request)
  File "/home/big/.local/lib/python3.8/site-packages/django/views/debug.py", line 99, in get_caller
    resolver_match = resolve(request.path)
  File "/home/big/.local/lib/python3.8/site-packages/django/urls/base.py", line 24, in resolve
    return get_resolver(urlconf).resolve(path)
  File "/home/big/.local/lib/python3.8/site-packages/django/urls/resolvers.py", line 663, in resolve
    for pattern in self.url_patterns:
  File "/home/big/.local/lib/python3.8/site-packages/django/utils/functional.py", line 57, in __get__
    res = instance.__dict__[self.name] = self.func(instance)
  File "/home/big/.local/lib/python3.8/site-packages/django/urls/resolvers.py", line 715, in url_patterns
    patterns = getattr(self.urlconf_module, "urlpatterns", self.urlconf_module)
  File "/home/big/.local/lib/python3.8/site-packages/django/utils/functional.py", line 57, in __get__
    res = instance.__dict__[self.name] = self.func(instance)
  File "/home/big/.local/lib/python3.8/site-packages/django/urls/resolvers.py", line 708, in urlconf_module
    return import_module(self.urlconf_name)
  File "/usr/lib/python3.8/importlib/__init__.py", line 127, in import_module
    return _bootstrap._gcd_import(name[level:], package, level)
  File "<frozen importlib._bootstrap>", line 1014, in _gcd_import
  File "<frozen importlib._bootstrap>", line 991, in _find_and_load
  File "<frozen importlib._bootstrap>", line 975, in _find_and_load_unlocked
  File "<frozen importlib._bootstrap>", line 671, in _load_unlocked
  File "<frozen importlib._bootstrap_external>", line 848, in exec_module
  File "<frozen importlib._bootstrap>", line 219, in _call_with_frames_removed
  File "/home/big/study/movie_rest/app/urls.py", line 22, in <module>
    from rest_api import views as rest_view
  File "/home/big/study/movie_rest/rest_api/views.py", line 40
    <<<<<<< HEAD
    ^
SyntaxError: invalid syntax

During handling of the above exception, another exception occurred:

Traceback (most recent call last):
  File "/home/big/.local/lib/python3.8/site-packages/django/core/handlers/exception.py", line 55, in inner
    response = get_response(request)
  File "/home/big/.local/lib/python3.8/site-packages/django/utils/deprecation.py", line 136, in __call__
    response = response or self.get_response(request)
  File "/home/big/.local/lib/python3.8/site-packages/django/core/handlers/exception.py", line 57, in inner
    response = response_for_exception(request, exc)
  File "/home/big/.local/lib/python3.8/site-packages/django/core/handlers/exception.py", line 140, in response_for_exception
    response = handle_uncaught_exception(
  File "/home/big/.local/lib/python3.8/site-packages/django/core/handlers/exception.py", line 181, in handle_uncaught_exception
    return debug.technical_500_response(request, *exc_info)
  File "/home/big/.local/lib/python3.8/site-packages/django/views/debug.py", line 66, in technical_500_response
    html = reporter.get_traceback_html()
  File "/home/big/.local/lib/python3.8/site-packages/django/views/debug.py", line 396, in get_traceback_html
    c = Context(self.get_traceback_data(), use_l10n=False)
  File "/home/big/.local/lib/python3.8/site-packages/django/views/debug.py", line 381, in get_traceback_data
    c["raising_view_name"] = get_caller(self.request)
  File "/home/big/.local/lib/python3.8/site-packages/django/views/debug.py", line 99, in get_caller
    resolver_match = resolve(request.path)
  File "/home/big/.local/lib/python3.8/site-packages/django/urls/base.py", line 24, in resolve
    return get_resolver(urlconf).resolve(path)
  File "/home/big/.local/lib/python3.8/site-packages/django/urls/resolvers.py", line 663, in resolve
    for pattern in self.url_patterns:
  File "/home/big/.local/lib/python3.8/site-packages/django/utils/functional.py", line 57, in __get__
    res = instance.__dict__[self.name] = self.func(instance)
  File "/home/big/.local/lib/python3.8/site-packages/django/urls/resolvers.py", line 715, in url_patterns
    patterns = getattr(self.urlconf_module, "urlpatterns", self.urlconf_module)
  File "/home/big/.local/lib/python3.8/site-packages/django/utils/functional.py", line 57, in __get__
    res = instance.__dict__[self.name] = self.func(instance)
  File "/home/big/.local/lib/python3.8/site-packages/django/urls/resolvers.py", line 708, in urlconf_module
    return import_module(self.urlconf_name)
  File "/usr/lib/python3.8/importlib/__init__.py", line 127, in import_module
    return _bootstrap._gcd_import(name[level:], package, level)
  File "<frozen importlib._bootstrap>", line 1014, in _gcd_import
  File "<frozen importlib._bootstrap>", line 991, in _find_and_load
  File "<frozen importlib._bootstrap>", line 975, in _find_and_load_unlocked
  File "<frozen importlib._bootstrap>", line 671, in _load_unlocked
  File "<frozen importlib._bootstrap_external>", line 848, in exec_module
  File "<frozen importlib._bootstrap>", line 219, in _call_with_frames_removed
  File "/home/big/study/movie_rest/app/urls.py", line 22, in <module>
    from rest_api import views as rest_view
  File "/home/big/study/movie_rest/rest_api/views.py", line 40
    <<<<<<< HEAD
    ^
SyntaxError: invalid syntax

During handling of the above exception, another exception occurred:

Traceback (most recent call last):
  File "/home/big/.local/lib/python3.8/site-packages/django/core/handlers/exception.py", line 55, in inner
    response = get_response(request)
  File "/home/big/.local/lib/python3.8/site-packages/django/utils/deprecation.py", line 136, in __call__
    response = response or self.get_response(request)
  File "/home/big/.local/lib/python3.8/site-packages/django/core/handlers/exception.py", line 57, in inner
    response = response_for_exception(request, exc)
  File "/home/big/.local/lib/python3.8/site-packages/django/core/handlers/exception.py", line 140, in response_for_exception
    response = handle_uncaught_exception(
  File "/home/big/.local/lib/python3.8/site-packages/django/core/handlers/exception.py", line 181, in handle_uncaught_exception
    return debug.technical_500_response(request, *exc_info)
  File "/home/big/.local/lib/python3.8/site-packages/django/views/debug.py", line 66, in technical_500_response
    html = reporter.get_traceback_html()
  File "/home/big/.local/lib/python3.8/site-packages/django/views/debug.py", line 396, in get_traceback_html
    c = Context(self.get_traceback_data(), use_l10n=False)
  File "/home/big/.local/lib/python3.8/site-packages/django/views/debug.py", line 381, in get_traceback_data
    c["raising_view_name"] = get_caller(self.request)
  File "/home/big/.local/lib/python3.8/site-packages/django/views/debug.py", line 99, in get_caller
    resolver_match = resolve(request.path)
  File "/home/big/.local/lib/python3.8/site-packages/django/urls/base.py", line 24, in resolve
    return get_resolver(urlconf).resolve(path)
  File "/home/big/.local/lib/python3.8/site-packages/django/urls/resolvers.py", line 663, in resolve
    for pattern in self.url_patterns:
  File "/home/big/.local/lib/python3.8/site-packages/django/utils/functional.py", line 57, in __get__
    res = instance.__dict__[self.name] = self.func(instance)
  File "/home/big/.local/lib/python3.8/site-packages/django/urls/resolvers.py", line 715, in url_patterns
    patterns = getattr(self.urlconf_module, "urlpatterns", self.urlconf_module)
  File "/home/big/.local/lib/python3.8/site-packages/django/utils/functional.py", line 57, in __get__
    res = instance.__dict__[self.name] = self.func(instance)
  File "/home/big/.local/lib/python3.8/site-packages/django/urls/resolvers.py", line 708, in urlconf_module
    return import_module(self.urlconf_name)
  File "/usr/lib/python3.8/importlib/__init__.py", line 127, in import_module
    return _bootstrap._gcd_import(name[level:], package, level)
  File "<frozen importlib._bootstrap>", line 1014, in _gcd_import
  File "<frozen importlib._bootstrap>", line 991, in _find_and_load
  File "<frozen importlib._bootstrap>", line 975, in _find_and_load_unlocked
  File "<frozen importlib._bootstrap>", line 671, in _load_unlocked
  File "<frozen importlib._bootstrap_external>", line 848, in exec_module
  File "<frozen importlib._bootstrap>", line 219, in _call_with_frames_removed
  File "/home/big/study/movie_rest/app/urls.py", line 22, in <module>
    from rest_api import views as rest_view
  File "/home/big/study/movie_rest/rest_api/views.py", line 40
    <<<<<<< HEAD
    ^
SyntaxError: invalid syntax

During handling of the above exception, another exception occurred:

Traceback (most recent call last):
  File "/home/big/.local/lib/python3.8/site-packages/django/core/handlers/exception.py", line 55, in inner
    response = get_response(request)
  File "/home/big/.local/lib/python3.8/site-packages/django/utils/deprecation.py", line 136, in __call__
    response = response or self.get_response(request)
  File "/home/big/.local/lib/python3.8/site-packages/django/core/handlers/exception.py", line 57, in inner
    response = response_for_exception(request, exc)
  File "/home/big/.local/lib/python3.8/site-packages/django/core/handlers/exception.py", line 140, in response_for_exception
    response = handle_uncaught_exception(
  File "/home/big/.local/lib/python3.8/site-packages/django/core/handlers/exception.py", line 181, in handle_uncaught_exception
    return debug.technical_500_response(request, *exc_info)
  File "/home/big/.local/lib/python3.8/site-packages/django/views/debug.py", line 66, in technical_500_response
    html = reporter.get_traceback_html()
  File "/home/big/.local/lib/python3.8/site-packages/django/views/debug.py", line 396, in get_traceback_html
    c = Context(self.get_traceback_data(), use_l10n=False)
  File "/home/big/.local/lib/python3.8/site-packages/django/views/debug.py", line 381, in get_traceback_data
    c["raising_view_name"] = get_caller(self.request)
  File "/home/big/.local/lib/python3.8/site-packages/django/views/debug.py", line 99, in get_caller
    resolver_match = resolve(request.path)
  File "/home/big/.local/lib/python3.8/site-packages/django/urls/base.py", line 24, in resolve
    return get_resolver(urlconf).resolve(path)
  File "/home/big/.local/lib/python3.8/site-packages/django/urls/resolvers.py", line 663, in resolve
    for pattern in self.url_patterns:
  File "/home/big/.local/lib/python3.8/site-packages/django/utils/functional.py", line 57, in __get__
    res = instance.__dict__[self.name] = self.func(instance)
  File "/home/big/.local/lib/python3.8/site-packages/django/urls/resolvers.py", line 715, in url_patterns
    patterns = getattr(self.urlconf_module, "urlpatterns", self.urlconf_module)
  File "/home/big/.local/lib/python3.8/site-packages/django/utils/functional.py", line 57, in __get__
    res = instance.__dict__[self.name] = self.func(instance)
  File "/home/big/.local/lib/python3.8/site-packages/django/urls/resolvers.py", line 708, in urlconf_module
    return import_module(self.urlconf_name)
  File "/usr/lib/python3.8/importlib/__init__.py", line 127, in import_module
    return _bootstrap._gcd_import(name[level:], package, level)
  File "<frozen importlib._bootstrap>", line 1014, in _gcd_import
  File "<frozen importlib._bootstrap>", line 991, in _find_and_load
  File "<frozen importlib._bootstrap>", line 975, in _find_and_load_unlocked
  File "<frozen importlib._bootstrap>", line 671, in _load_unlocked
  File "<frozen importlib._bootstrap_external>", line 848, in exec_module
  File "<frozen importlib._bootstrap>", line 219, in _call_with_frames_removed
  File "/home/big/study/movie_rest/app/urls.py", line 22, in <module>
    from rest_api import views as rest_view
  File "/home/big/study/movie_rest/rest_api/views.py", line 40
    <<<<<<< HEAD
    ^
SyntaxError: invalid syntax

During handling of the above exception, another exception occurred:

Traceback (most recent call last):
  File "/home/big/.local/lib/python3.8/site-packages/django/core/handlers/exception.py", line 55, in inner
    response = get_response(request)
  File "/home/big/.local/lib/python3.8/site-packages/django/utils/deprecation.py", line 136, in __call__
    response = response or self.get_response(request)
  File "/home/big/.local/lib/python3.8/site-packages/django/core/handlers/exception.py", line 57, in inner
    response = response_for_exception(request, exc)
  File "/home/big/.local/lib/python3.8/site-packages/django/core/handlers/exception.py", line 140, in response_for_exception
    response = handle_uncaught_exception(
  File "/home/big/.local/lib/python3.8/site-packages/django/core/handlers/exception.py", line 181, in handle_uncaught_exception
    return debug.technical_500_response(request, *exc_info)
  File "/home/big/.local/lib/python3.8/site-packages/django/views/debug.py", line 66, in technical_500_response
    html = reporter.get_traceback_html()
  File "/home/big/.local/lib/python3.8/site-packages/django/views/debug.py", line 396, in get_traceback_html
    c = Context(self.get_traceback_data(), use_l10n=False)
  File "/home/big/.local/lib/python3.8/site-packages/django/views/debug.py", line 381, in get_traceback_data
    c["raising_view_name"] = get_caller(self.request)
  File "/home/big/.local/lib/python3.8/site-packages/django/views/debug.py", line 99, in get_caller
    resolver_match = resolve(request.path)
  File "/home/big/.local/lib/python3.8/site-packages/django/urls/base.py", line 24, in resolve
    return get_resolver(urlconf).resolve(path)
  File "/home/big/.local/lib/python3.8/site-packages/django/urls/resolvers.py", line 663, in resolve
    for pattern in self.url_patterns:
  File "/home/big/.local/lib/python3.8/site-packages/django/utils/functional.py", line 57, in __get__
    res = instance.__dict__[self.name] = self.func(instance)
  File "/home/big/.local/lib/python3.8/site-packages/django/urls/resolvers.py", line 715, in url_patterns
    patterns = getattr(self.urlconf_module, "urlpatterns", self.urlconf_module)
  File "/home/big/.local/lib/python3.8/site-packages/django/utils/functional.py", line 57, in __get__
    res = instance.__dict__[self.name] = self.func(instance)
  File "/home/big/.local/lib/python3.8/site-packages/django/urls/resolvers.py", line 708, in urlconf_module
    return import_module(self.urlconf_name)
  File "/usr/lib/python3.8/importlib/__init__.py", line 127, in import_module
    return _bootstrap._gcd_import(name[level:], package, level)
  File "<frozen importlib._bootstrap>", line 1014, in _gcd_import
  File "<frozen importlib._bootstrap>", line 991, in _find_and_load
  File "<frozen importlib._bootstrap>", line 975, in _find_and_load_unlocked
  File "<frozen importlib._bootstrap>", line 671, in _load_unlocked
  File "<frozen importlib._bootstrap_external>", line 848, in exec_module
  File "<frozen importlib._bootstrap>", line 219, in _call_with_frames_removed
  File "/home/big/study/movie_rest/app/urls.py", line 22, in <module>
    from rest_api import views as rest_view
  File "/home/big/study/movie_rest/rest_api/views.py", line 40
    <<<<<<< HEAD
    ^
SyntaxError: invalid syntax

During handling of the above exception, another exception occurred:

Traceback (most recent call last):
  File "/home/big/.local/lib/python3.8/site-packages/django/core/handlers/exception.py", line 55, in inner
    response = get_response(request)
  File "/home/big/.local/lib/python3.8/site-packages/django/utils/deprecation.py", line 136, in __call__
    response = response or self.get_response(request)
  File "/home/big/.local/lib/python3.8/site-packages/django/core/handlers/exception.py", line 57, in inner
    response = response_for_exception(request, exc)
  File "/home/big/.local/lib/python3.8/site-packages/django/core/handlers/exception.py", line 140, in response_for_exception
    response = handle_uncaught_exception(
  File "/home/big/.local/lib/python3.8/site-packages/django/core/handlers/exception.py", line 181, in handle_uncaught_exception
    return debug.technical_500_response(request, *exc_info)
  File "/home/big/.local/lib/python3.8/site-packages/django/views/debug.py", line 66, in technical_500_response
    html = reporter.get_traceback_html()
  File "/home/big/.local/lib/python3.8/site-packages/django/views/debug.py", line 396, in get_traceback_html
    c = Context(self.get_traceback_data(), use_l10n=False)
  File "/home/big/.local/lib/python3.8/site-packages/django/views/debug.py", line 381, in get_traceback_data
    c["raising_view_name"] = get_caller(self.request)
  File "/home/big/.local/lib/python3.8/site-packages/django/views/debug.py", line 99, in get_caller
    resolver_match = resolve(request.path)
  File "/home/big/.local/lib/python3.8/site-packages/django/urls/base.py", line 24, in resolve
    return get_resolver(urlconf).resolve(path)
  File "/home/big/.local/lib/python3.8/site-packages/django/urls/resolvers.py", line 663, in resolve
    for pattern in self.url_patterns:
  File "/home/big/.local/lib/python3.8/site-packages/django/utils/functional.py", line 57, in __get__
    res = instance.__dict__[self.name] = self.func(instance)
  File "/home/big/.local/lib/python3.8/site-packages/django/urls/resolvers.py", line 715, in url_patterns
    patterns = getattr(self.urlconf_module, "urlpatterns", self.urlconf_module)
  File "/home/big/.local/lib/python3.8/site-packages/django/utils/functional.py", line 57, in __get__
    res = instance.__dict__[self.name] = self.func(instance)
  File "/home/big/.local/lib/python3.8/site-packages/django/urls/resolvers.py", line 708, in urlconf_module
    return import_module(self.urlconf_name)
  File "/usr/lib/python3.8/importlib/__init__.py", line 127, in import_module
    return _bootstrap._gcd_import(name[level:], package, level)
  File "<frozen importlib._bootstrap>", line 1014, in _gcd_import
  File "<frozen importlib._bootstrap>", line 991, in _find_and_load
  File "<frozen importlib._bootstrap>", line 975, in _find_and_load_unlocked
  File "<frozen importlib._bootstrap>", line 671, in _load_unlocked
  File "<frozen importlib._bootstrap_external>", line 848, in exec_module
  File "<frozen importlib._bootstrap>", line 219, in _call_with_frames_removed
  File "/home/big/study/movie_rest/app/urls.py", line 22, in <module>
    from rest_api import views as rest_view
  File "/home/big/study/movie_rest/rest_api/views.py", line 40
    <<<<<<< HEAD
    ^
SyntaxError: invalid syntax

During handling of the above exception, another exception occurred:

Traceback (most recent call last):
  File "/home/big/.local/lib/python3.8/site-packages/django/core/handlers/exception.py", line 55, in inner
    response = get_response(request)
  File "/home/big/.local/lib/python3.8/site-packages/django/utils/deprecation.py", line 136, in __call__
    response = response or self.get_response(request)
  File "/home/big/.local/lib/python3.8/site-packages/django/core/handlers/exception.py", line 57, in inner
    response = response_for_exception(request, exc)
  File "/home/big/.local/lib/python3.8/site-packages/django/core/handlers/exception.py", line 140, in response_for_exception
    response = handle_uncaught_exception(
  File "/home/big/.local/lib/python3.8/site-packages/django/core/handlers/exception.py", line 181, in handle_uncaught_exception
    return debug.technical_500_response(request, *exc_info)
  File "/home/big/.local/lib/python3.8/site-packages/django/views/debug.py", line 66, in technical_500_response
    html = reporter.get_traceback_html()
  File "/home/big/.local/lib/python3.8/site-packages/django/views/debug.py", line 396, in get_traceback_html
    c = Context(self.get_traceback_data(), use_l10n=False)
  File "/home/big/.local/lib/python3.8/site-packages/django/views/debug.py", line 381, in get_traceback_data
    c["raising_view_name"] = get_caller(self.request)
  File "/home/big/.local/lib/python3.8/site-packages/django/views/debug.py", line 99, in get_caller
    resolver_match = resolve(request.path)
  File "/home/big/.local/lib/python3.8/site-packages/django/urls/base.py", line 24, in resolve
    return get_resolver(urlconf).resolve(path)
  File "/home/big/.local/lib/python3.8/site-packages/django/urls/resolvers.py", line 663, in resolve
    for pattern in self.url_patterns:
  File "/home/big/.local/lib/python3.8/site-packages/django/utils/functional.py", line 57, in __get__
    res = instance.__dict__[self.name] = self.func(instance)
  File "/home/big/.local/lib/python3.8/site-packages/django/urls/resolvers.py", line 715, in url_patterns
    patterns = getattr(self.urlconf_module, "urlpatterns", self.urlconf_module)
  File "/home/big/.local/lib/python3.8/site-packages/django/utils/functional.py", line 57, in __get__
    res = instance.__dict__[self.name] = self.func(instance)
  File "/home/big/.local/lib/python3.8/site-packages/django/urls/resolvers.py", line 708, in urlconf_module
    return import_module(self.urlconf_name)
  File "/usr/lib/python3.8/importlib/__init__.py", line 127, in import_module
    return _bootstrap._gcd_import(name[level:], package, level)
  File "<frozen importlib._bootstrap>", line 1014, in _gcd_import
  File "<frozen importlib._bootstrap>", line 991, in _find_and_load
  File "<frozen importlib._bootstrap>", line 975, in _find_and_load_unlocked
  File "<frozen importlib._bootstrap>", line 671, in _load_unlocked
  File "<frozen importlib._bootstrap_external>", line 848, in exec_module
  File "<frozen importlib._bootstrap>", line 219, in _call_with_frames_removed
  File "/home/big/study/movie_rest/app/urls.py", line 22, in <module>
    from rest_api import views as rest_view
  File "/home/big/study/movie_rest/rest_api/views.py", line 40
    <<<<<<< HEAD
    ^
SyntaxError: invalid syntax

During handling of the above exception, another exception occurred:

Traceback (most recent call last):
  File "/home/big/.local/lib/python3.8/site-packages/django/core/handlers/exception.py", line 55, in inner
    response = get_response(request)
  File "/home/big/.local/lib/python3.8/site-packages/django/utils/deprecation.py", line 136, in __call__
    response = response or self.get_response(request)
  File "/home/big/.local/lib/python3.8/site-packages/django/core/handlers/exception.py", line 57, in inner
    response = response_for_exception(request, exc)
  File "/home/big/.local/lib/python3.8/site-packages/django/core/handlers/exception.py", line 140, in response_for_exception
    response = handle_uncaught_exception(
  File "/home/big/.local/lib/python3.8/site-packages/django/core/handlers/exception.py", line 181, in handle_uncaught_exception
    return debug.technical_500_response(request, *exc_info)
  File "/home/big/.local/lib/python3.8/site-packages/django/views/debug.py", line 66, in technical_500_response
    html = reporter.get_traceback_html()
  File "/home/big/.local/lib/python3.8/site-packages/django/views/debug.py", line 396, in get_traceback_html
    c = Context(self.get_traceback_data(), use_l10n=False)
  File "/home/big/.local/lib/python3.8/site-packages/django/views/debug.py", line 381, in get_traceback_data
    c["raising_view_name"] = get_caller(self.request)
  File "/home/big/.local/lib/python3.8/site-packages/django/views/debug.py", line 99, in get_caller
    resolver_match = resolve(request.path)
  File "/home/big/.local/lib/python3.8/site-packages/django/urls/base.py", line 24, in resolve
    return get_resolver(urlconf).resolve(path)
  File "/home/big/.local/lib/python3.8/site-packages/django/urls/resolvers.py", line 663, in resolve
    for pattern in self.url_patterns:
  File "/home/big/.local/lib/python3.8/site-packages/django/utils/functional.py", line 57, in __get__
    res = instance.__dict__[self.name] = self.func(instance)
  File "/home/big/.local/lib/python3.8/site-packages/django/urls/resolvers.py", line 715, in url_patterns
    patterns = getattr(self.urlconf_module, "urlpatterns", self.urlconf_module)
  File "/home/big/.local/lib/python3.8/site-packages/django/utils/functional.py", line 57, in __get__
    res = instance.__dict__[self.name] = self.func(instance)
  File "/home/big/.local/lib/python3.8/site-packages/django/urls/resolvers.py", line 708, in urlconf_module
    return import_module(self.urlconf_name)
  File "/usr/lib/python3.8/importlib/__init__.py", line 127, in import_module
    return _bootstrap._gcd_import(name[level:], package, level)
  File "<frozen importlib._bootstrap>", line 1014, in _gcd_import
  File "<frozen importlib._bootstrap>", line 991, in _find_and_load
  File "<frozen importlib._bootstrap>", line 975, in _find_and_load_unlocked
  File "<frozen importlib._bootstrap>", line 671, in _load_unlocked
  File "<frozen importlib._bootstrap_external>", line 848, in exec_module
  File "<frozen importlib._bootstrap>", line 219, in _call_with_frames_removed
  File "/home/big/study/movie_rest/app/urls.py", line 22, in <module>
    from rest_api import views as rest_view
  File "/home/big/study/movie_rest/rest_api/views.py", line 40
    <<<<<<< HEAD
    ^
SyntaxError: invalid syntax

During handling of the above exception, another exception occurred:

Traceback (most recent call last):
  File "/home/big/.local/lib/python3.8/site-packages/gunicorn/workers/sync.py", line 136, in handle
    self.handle_request(listener, req, client, addr)
  File "/home/big/.local/lib/python3.8/site-packages/gunicorn/workers/sync.py", line 179, in handle_request
    respiter = self.wsgi(environ, resp.start_response)
  File "/home/big/.local/lib/python3.8/site-packages/django/core/handlers/wsgi.py", line 131, in __call__
    response = self.get_response(request)
  File "/home/big/.local/lib/python3.8/site-packages/django/core/handlers/base.py", line 140, in get_response
    response = self._middleware_chain(request)
  File "/home/big/.local/lib/python3.8/site-packages/django/core/handlers/exception.py", line 57, in inner
    response = response_for_exception(request, exc)
  File "/home/big/.local/lib/python3.8/site-packages/django/core/handlers/exception.py", line 140, in response_for_exception
    response = handle_uncaught_exception(
  File "/home/big/.local/lib/python3.8/site-packages/django/core/handlers/exception.py", line 181, in handle_uncaught_exception
    return debug.technical_500_response(request, *exc_info)
  File "/home/big/.local/lib/python3.8/site-packages/django/views/debug.py", line 66, in technical_500_response
    html = reporter.get_traceback_html()
  File "/home/big/.local/lib/python3.8/site-packages/django/views/debug.py", line 396, in get_traceback_html
    c = Context(self.get_traceback_data(), use_l10n=False)
  File "/home/big/.local/lib/python3.8/site-packages/django/views/debug.py", line 381, in get_traceback_data
    c["raising_view_name"] = get_caller(self.request)
  File "/home/big/.local/lib/python3.8/site-packages/django/views/debug.py", line 99, in get_caller
    resolver_match = resolve(request.path)
  File "/home/big/.local/lib/python3.8/site-packages/django/urls/base.py", line 24, in resolve
    return get_resolver(urlconf).resolve(path)
  File "/home/big/.local/lib/python3.8/site-packages/django/urls/resolvers.py", line 663, in resolve
    for pattern in self.url_patterns:
  File "/home/big/.local/lib/python3.8/site-packages/django/utils/functional.py", line 57, in __get__
    res = instance.__dict__[self.name] = self.func(instance)
  File "/home/big/.local/lib/python3.8/site-packages/django/urls/resolvers.py", line 715, in url_patterns
    patterns = getattr(self.urlconf_module, "urlpatterns", self.urlconf_module)
  File "/home/big/.local/lib/python3.8/site-packages/django/utils/functional.py", line 57, in __get__
    res = instance.__dict__[self.name] = self.func(instance)
  File "/home/big/.local/lib/python3.8/site-packages/django/urls/resolvers.py", line 708, in urlconf_module
    return import_module(self.urlconf_name)
  File "/usr/lib/python3.8/importlib/__init__.py", line 127, in import_module
    return _bootstrap._gcd_import(name[level:], package, level)
  File "<frozen importlib._bootstrap>", line 1014, in _gcd_import
  File "<frozen importlib._bootstrap>", line 991, in _find_and_load
  File "<frozen importlib._bootstrap>", line 975, in _find_and_load_unlocked
  File "<frozen importlib._bootstrap>", line 671, in _load_unlocked
  File "<frozen importlib._bootstrap_external>", line 848, in exec_module
  File "<frozen importlib._bootstrap>", line 219, in _call_with_frames_removed
  File "/home/big/study/movie_rest/app/urls.py", line 22, in <module>
    from rest_api import views as rest_view
  File "/home/big/study/movie_rest/rest_api/views.py", line 40
    <<<<<<< HEAD
    ^
SyntaxError: invalid syntax
[2022-10-06 07:10:45 +0000] [1221] [INFO] Parent changed, shutting down: <Worker 1221>
[2022-10-06 07:10:45 +0000] [1221] [INFO] Worker exiting (pid: 1221)
